Workbook
Name ProblemCategoryList: 'Lists'!$A$2:$A$10
Name PriorityList: 'Lists'!$B$2:$B$5
Name WorkOrderStatusList: 'Lists'!$C$2:$C$10
Name AssignmentRoleList: 'Lists'!$D$2:$D$4
Name AssignmentStatusList: 'Lists'!$E$2:$E$7
Name MachineStatusList: 'Lists'!$F$2:$F$5
Name CriticalityList: 'Lists'!$G$2:$G$4
Name SkillGroupList: 'Lists'!$H$2:$H$8
Name AppRoleList: 'Lists'!$I$2:$I$5
Name PartCategoryList: 'Lists'!$J$2:$J$10
Name UnitList: 'Lists'!$K$2:$K$7
Name BooleanList: 'Lists'!$L$2:$L$3
Name RatingList: 'Lists'!$M$2:$M$6

Sheet 00_คู่มือ
A1: คู่มือระบบแจ้งซ่อมเครื่องจักร CMMS
A2: ต้นแบบภาษาไทยสำหรับ Excel, Google Sheets และ AppSheet | มีข้อมูลตัวอย่าง ให้ลบรายการ DEMO/ตัวอย่างก่อนใช้งานจริง
A4: โครงสร้างและความสัมพันธ์ตาราง
A5: ลำดับ | B5: ตาราง | C5: หน้าที่ | D5: ความสัมพันธ์หลัก | E5: Key | F5: หมายเหตุ
A6: 1 | B6: Machines | C6: ทะเบียนเครื่องจักร | D6: 1 เครื่อง → หลาย WorkOrders / RepairHistory | E6: MachineID | F6: ใช้ MachineCode เป็น Label/Barcode
A7: 2 | B7: Technicians | C7: ทะเบียนช่างและสิทธิ์ | D7: 1 ช่าง → หลาย Assignments / RepairHistory | E7: TechnicianID | F7: รองรับ Technician และ Manager
A8: 3 | B8: WorkOrders | C8: ใบแจ้งซ่อมและสถานะงาน | D8: อ้าง Machines และ Primary Technician | E8: WorkOrderID | F8: ตารางธุรกรรมหลัก
A9: 4 | B9: Assignments | C9: การมอบหมาย/รับงานของช่าง | D9: หลายช่างต่อ 1 WorkOrder | E9: AssignmentID | F9: WorkOrderID และ TechnicianID เป็น Ref
A10: 5 | B10: RepairHistory | C10: ประวัติการซ่อมที่ปิดแล้ว | D10: 1 แถวต่อเหตุขัดข้องที่ปิด | E10: RepairHistoryID | F10: ใช้คำนวณ Downtime, MTTR, MTBF
A11: 6 | B11: Parts | C11: ทะเบียนอะไหล่/สต็อก | D11: 1 อะไหล่ → หลาย PartUsage | E11: PartID | F11: เตือนต่ำกว่าจุดสั่งซื้อ
A12: 7 | B12: PartUsage | C12: รายการอะไหล่ที่ใช้ | D12: หลายรายการต่อ 1 WorkOrder | E12: PartUsageID | F12: LineTotal = Quantity × UnitCost
A13: 8 | B13: StatusLog | C13: ประวัติเปลี่ยนสถานะ | D13: หลายรายการต่อ 1 WorkOrder | E13: StatusLogID | F13: สร้างอัตโนมัติด้วย Bot
A14: 9 | B14: Settings | C14: รายการตัวเลือกกลาง | D14: ใช้เป็น Valid If / Enum | E14: SettingID | F14: เพิ่มค่ารายการโดยไม่แก้โครงสร้างแอป
A16: ขั้นตอนนำไปใช้กับ Google Sheets และ AppSheet
A17: ขั้น | B17: หัวข้อ | C17: การดำเนินการ | D17: ผลที่ต้องตรวจ
A18: 1 | B18: อัปโหลดไฟล์ | C18: นำไฟล์ .xlsx เข้า Google Drive แล้ว Open with → Google Sheets | D18: ตรวจว่าชื่อชีตและหัวคอลัมน์ไม่เปลี่ยน
A19: 2 | B19: ตั้งค่า Locale | C19: File → Settings → Locale = Thailand, Time zone = Bangkok | D19: วันเวลาแสดงถูกต้อง
A20: 3 | B20: สร้าง AppSheet | C20: appsheet.com → Make a new app → Start with your own data | D20: เลือก Google Sheets ที่นำเข้า
A21: 4 | B21: เพิ่มตาราง | C21: เพิ่ม Machines, Technicians, WorkOrders, Assignments, RepairHistory, Parts, PartUsage, StatusLog, Settings | D21: ไม่เพิ่ม Dashboard, คู่มือ และ Lists
A22: 5 | B22: กำหนด Key/Ref | C22: ใช้ AppSheet_Config เป็นคู่มือ Type, Key, Label, Ref | D22: กด Regenerate structure ทีละตาราง
A23: 6 | B23: ตั้งค่า Workflow | C23: สร้าง Actions: Assign, Accept, Start, Complete, Verify, Close | D23: เปลี่ยนสถานะและเวลาใน Action เดียว
A24: 7 | B24: สร้าง Bots | C24: บันทึก StatusLog ทุกครั้งที่สถานะเปลี่ยน และสร้าง RepairHistory เมื่อ Closed | D24: ทดสอบไม่ให้สร้างซ้ำ
A25: 8 | B25: Security | C25: เปิด Require sign-in และใช้ Security Filter ตามบทบาท | D25: ทดสอบ Requester/Technician/Manager
A26: 9 | B26: Dashboard | C26: สร้าง Slices งานเปิด งานช่าง และงานเกิน SLA; รวมเป็น Dashboard View | D26: ใช้ชีต Dashboard เป็นตัวอย่าง KPI
A27: 10 | B27: ทดสอบและ Deploy | C27: ลบข้อมูลตัวอย่าง เปลี่ยนอีเมลจริง รัน Deployment Check | D27: สำรองไฟล์ก่อนลบข้อมูลตัวอย่าง
A29: เวิร์กโฟลว์สถานะที่แนะนำ
A30: New → Assigned → Accepted → In Progress → Waiting Parts (ถ้ามี) → Completed → Verified → Closed

Sheet Dashboard
A1: แดชบอร์ด CMMS — Downtime, MTTR และ MTBF
A2: ข้อมูลตัวอย่าง ณ 23 ตุลาคม 2026 | สูตรออกแบบให้ใช้ได้ทั้ง Excel และ Google Sheets
A4: จำนวนเครื่องจักร | D4: ใบงานเปิด | G4: Downtime รวม (ชม.) | J4: MTTR เฉลี่ย (ชม.) | M4: MTBF เฉลี่ย (ชม.)
A5: =COUNTA(Machines!A:A)-1 | D5: =COUNTIFS(WorkOrders!K:K,"<>Closed",WorkOrders!K:K,"<>Cancelled") | G5: =SUM(RepairHistory!L:L)/60 | J5: =AVERAGE(RepairHistory!M:M)/60 | M5: =AVERAGE(RepairHistory!N:N)
A7: งานปิดแล้ว | D7: งานเกิน SLA | G7: SLA On-time | J7: คะแนนเฉลี่ย | M7: ค่าใช้จ่ายรวม
A8: =COUNTIF(WorkOrders!K:K,"Closed") | D8: =COUNTIFS(WorkOrders!U:U,"Overdue",WorkOrders!K:K,"<>Closed") | G8: =COUNTIF(WorkOrders!U:U,"On Time")/COUNTIF(WorkOrders!K:K,"Closed") | J8: =AVERAGE(WorkOrders!AE:AE) | M8: =SUM(RepairHistory!Q:Q)
A11: MachineCode | B11: ชื่อเครื่องจักร | C11: Downtime (ชม.) | D11: MTTR (ชม.) | E11: MTBF (ชม.) | F11: จำนวนครั้งซ่อม
A12: PRESS-01 | B12: เครื่องปั๊มไฮดรอลิก 1 | C12: =SUMIF(RepairHistory!C:C,"MCH-001",RepairHistory!L:L)/60 | D12: =IFERROR(AVERAGEIF(RepairHistory!C:C,"MCH-001",RepairHistory!M:M)/60,0) | E12: =IFERROR(AVERAGEIF(RepairHistory!C:C,"MCH-001",RepairHistory!N:N),0) | F12: =COUNTIF(RepairHistory!C:C,"MCH-001")
A13: CONV-01 | B13: สายพานลำเลียง 1 | C13: =SUMIF(RepairHistory!C:C,"MCH-002",RepairHistory!L:L)/60 | D13: =IFERROR(AVERAGEIF(RepairHistory!C:C,"MCH-002",RepairHistory!M:M)/60,0) | E13: =IFERROR(AVERAGEIF(RepairHistory!C:C,"MCH-002",RepairHistory!N:N),0) | F13: =COUNTIF(RepairHistory!C:C,"MCH-002")
A14: COMP-01 | B14: เครื่องอัดอากาศ 1 | C14: =SUMIF(RepairHistory!C:C,"MCH-003",RepairHistory!L:L)/60 | D14: =IFERROR(AVERAGEIF(RepairHistory!C:C,"MCH-003",RepairHistory!M:M)/60,0) | E14: =IFERROR(AVERAGEIF(RepairHistory!C:C,"MCH-003",RepairHistory!N:N),0) | F14: =COUNTIF(RepairHistory!C:C,"MCH-003")
A15: PACK-01 | B15: เครื่องซีลบรรจุภัณฑ์ 1 | C15: =SUMIF(RepairHistory!C:C,"MCH-004",RepairHistory!L:L)/60 | D15: =IFERROR(AVERAGEIF(RepairHistory!C:C,"MCH-004",RepairHistory!M:M)/60,0) | E15: =IFERROR(AVERAGEIF(RepairHistory!C:C,"MCH-004",RepairHistory!N:N),0) | F15: =COUNTIF(RepairHistory!C:C,"MCH-004")
A16: PUMP-01 | B16: ปั๊มน้ำหล่อเย็น 1 | C16: =SUMIF(RepairHistory!C:C,"MCH-005",RepairHistory!L:L)/60 | D16: =IFERROR(AVERAGEIF(RepairHistory!C:C,"MCH-005",RepairHistory!M:M)/60,0) | E16: =IFERROR(AVERAGEIF(RepairHistory!C:C,"MCH-005",RepairHistory!N:N),0) | F16: =COUNTIF(RepairHistory!C:C,"MCH-005")
A17: CNC-01 | B17: เครื่อง CNC 1 | C17: =SUMIF(RepairHistory!C:C,"MCH-006",RepairHistory!L:L)/60 | D17: =IFERROR(AVERAGEIF(RepairHistory!C:C,"MCH-006",RepairHistory!M:M)/60,0) | E17: =IFERROR(AVERAGEIF(RepairHistory!C:C,"MCH-006",RepairHistory!N:N),0) | F17: =COUNTIF(RepairHistory!C:C,"MCH-006")
A21: สถานะใบงาน | B21: จำนวน | D21: เดือน | E21: งานปิด | F21: Downtime (ชม.)
A22: New | B22: =COUNTIF(WorkOrders!K:K,A22) | D22: 46143 | E22: =COUNTIFS(RepairHistory!S:S,">="&D22,RepairHistory!S:S,"<"&EDATE(D22,1)) | F22: =SUMIFS(RepairHistory!L:L,RepairHistory!S:S,">="&D22,RepairHistory!S:S,"<"&EDATE(D22,1))/60
A23: Assigned | B23: =COUNTIF(WorkOrders!K:K,A23) | D23: 46174 | E23: =COUNTIFS(RepairHistory!S:S,">="&D23,RepairHistory!S:S,"<"&EDATE(D23,1)) | F23: =SUMIFS(RepairHistory!L:L,RepairHistory!S:S,">="&D23,RepairHistory!S:S,"<"&EDATE(D23,1))/60
A24: Accepted | B24: =COUNTIF(WorkOrders!K:K,A24) | D24: 46204 | E24: =COUNTIFS(RepairHistory!S:S,">="&D24,RepairHistory!S:S,"<"&EDATE(D24,1)) | F24: =SUMIFS(RepairHistory!L:L,RepairHistory!S:S,">="&D24,RepairHistory!S:S,"<"&EDATE(D24,1))/60
A25: In Progress | B25: =COUNTIF(WorkOrders!K:K,A25) | D25: 46235 | E25: =COUNTIFS(RepairHistory!S:S,">="&D25,RepairHistory!S:S,"<"&EDATE(D25,1)) | F25: =SUMIFS(RepairHistory!L:L,RepairHistory!S:S,">="&D25,RepairHistory!S:S,"<"&EDATE(D25,1))/60
A26: Waiting Parts | B26: =COUNTIF(WorkOrders!K:K,A26) | D26: 46266 | E26: =COUNTIFS(RepairHistory!S:S,">="&D26,RepairHistory!S:S,"<"&EDATE(D26,1)) | F26: =SUMIFS(RepairHistory!L:L,RepairHistory!S:S,">="&D26,RepairHistory!S:S,"<"&EDATE(D26,1))/60
A27: Completed | B27: =COUNTIF(WorkOrders!K:K,A27) | D27: 46296 | E27: =COUNTIFS(RepairHistory!S:S,">="&D27,RepairHistory!S:S,"<"&EDATE(D27,1)) | F27: =SUMIFS(RepairHistory!L:L,RepairHistory!S:S,">="&D27,RepairHistory!S:S,"<"&EDATE(D27,1))/60
A28: Verified | B28: =COUNTIF(WorkOrders!K:K,A28)
A29: Closed | B29: =COUNTIF(WorkOrders!K:K,A29)
A30: Cancelled | B30: =COUNTIF(WorkOrders!K:K,A30)
A33: นิยาม KPI
A34: Downtime = เวลาที่เครื่องหยุดจาก FailureStart ถึง ReturnedToService
A35: MTTR = ค่าเฉลี่ย RepairMinutes ÷ 60 ของงานซ่อมที่ปิดแล้ว
A36: MTBF = ค่าเฉลี่ยชั่วโมงระหว่าง ReturnedToService ครั้งก่อนกับ FailureStart ครั้งถัดไปของเครื่องเดียวกัน

Sheet Machines
A1: MachineID | B1: MachineCode | C1: MachineNameTH | D1: Category | E1: Location | F1: ProductionLine | G1: Manufacturer | H1: Model | I1: SerialNo | J1: CommissionDate | K1: Criticality | L1: MachineStatus | M1: PlannedHoursPerDay | N1: LastPMDate | O1: NextPMDate | P1: OwnerDepartment | Q1: Image | R1: BarcodeValue | S1: Active | T1: Notes
A2: MCH-001 | B2: PRESS-01 | C2: เครื่องปั๊มไฮดรอลิก 1 | D2: Press | E2: อาคาร A | F2: Line 1 | G2: Thai Press | H2: HP-500 | I2: SN-P001 | J2: 44287 | K2: High | L2: Running | M2: 20 | N2: 46280 | O2: 46371 | P2: Production | R2: PRESS-01 | S2: TRUE | T2: เครื่องจักรวิกฤตของ Line 1
A3: MCH-002 | B3: CONV-01 | C3: สายพานลำเลียง 1 | D3: Conveyor | E3: อาคาร A | F3: Line 1 | G3: MoveFast | H3: CV-120 | I3: SN-C001 | J3: 44581 | K3: Medium | L3: Running | M3: 20 | N3: 46235 | O3: 46327 | P3: Production | R3: CONV-01 | S3: TRUE
A4: MCH-003 | B4: COMP-01 | C4: เครื่องอัดอากาศ 1 | D4: Compressor | E4: Utility Room | F4: Utility | G4: AirPro | H4: AP-75 | I4: SN-A001 | J4: 44023 | K4: High | L4: Running | M4: 24 | N4: 46213 | O4: 46305 | P4: Engineering | R4: COMP-01 | S4: TRUE | T4: มีเครื่องสำรอง 1 เครื่อง
A5: MCH-004 | B5: PACK-01 | C5: เครื่องซีลบรรจุภัณฑ์ 1 | D5: Packaging | E5: อาคาร B | F5: Packing | G5: PackMaster | H5: PM-20 | I5: SN-K001 | J5: 44993 | K5: Medium | L5: Running | M5: 18 | N5: 46270 | O5: 46361 | P5: Packing | R5: PACK-01 | S5: TRUE
A6: MCH-005 | B6: PUMP-01 | C6: ปั๊มน้ำหล่อเย็น 1 | D6: Pump | E6: Utility Room | F6: Utility | G6: FlowTech | H6: FT-40 | I6: SN-W001 | J6: 43799 | K6: Medium | L6: Under Repair | M6: 24 | N6: 46203 | O6: 46386 | P6: Engineering | R6: PUMP-01 | S6: TRUE
A7: MCH-006 | B7: CNC-01 | C7: เครื่อง CNC 1 | D7: CNC | E7: อาคาร C | F7: Machining | G7: PrecisionWorks | H7: CNC-850 | I7: SN-N001 | J7: 45337 | K7: High | L7: Running | M7: 16 | N7: 46295 | O7: 46356 | P7: Machining | R7: CNC-01 | S7: TRUE

Sheet Technicians
A1: TechnicianID | B1: EmployeeCode | C1: FullNameTH | D1: Team | E1: SkillGroup | F1: Phone | G1: Email | H1: AppRole | I1: HourlyRate | J1: Active
A2: TECH-001 | B2: E1001 | C2: สมชาย ช่างกล | D2: Maintenance A | E2: Mechanical | F2: 0810001001 | G2: somchai@example.com | H2: Technician | I2: 350 | J2: TRUE
A3: TECH-002 | B3: E1002 | C3: สมหญิง ไฟฟ้า | D3: Maintenance A | E3: Electrical | F3: 0810001002 | G3: somying@example.com | H3: Technician | I3: 380 | J3: TRUE
A4: TECH-003 | B4: E1003 | C4: วิชัย ระบบลม | D4: Utility | E4: Pneumatic | F4: 0810001003 | G4: wichai@example.com | H4: Technician | I4: 360 | J4: TRUE
A5: TECH-004 | B5: E1004 | C5: อารีย์ อัตโนมัติ | D5: Maintenance B | E5: Automation | F5: 0810001004 | G5: aree@example.com | H5: Technician | I5: 420 | J5: TRUE
A6: TECH-005 | B6: E1005 | C6: กิตติ หัวหน้าซ่อม | D6: Maintenance | E6: Management | F6: 0810001005 | G6: kitti@example.com | H6: Manager | I6: 500 | J6: TRUE

Sheet WorkOrders
A1: WorkOrderID | B1: RequestDateTime | C1: RequesterName | D1: RequesterEmail | E1: MachineID | F1: ProblemCategory | G1: ProblemDescription | H1: Priority | I1: MachineStopped | J1: PhotoBefore | K1: WorkOrderStatus | L1: PrimaryTechnicianID | M1: AssignedAt | N1: AcceptedAt | O1: StartedAt | P1: CompletedAt | Q1: VerifiedAt | R1: ClosedAt | S1: SLAHours | T1: DueAt | U1: SLAStatus | V1: DowntimeMinutes | W1: RootCause | X1: RepairAction | Y1: PhotoAfter | Z1: LaborHours | AA1: LaborCost | AB1: PartsCost | AC1: TotalCost | AD1: RequesterConfirmed | AE1: Rating | AF1: SafetyIssue | AG1: LastUpdated | AH1: Notes
A2: WO-2026-0001 | B2: 46152.333 | C2: อนันต์ ฝ่ายผลิต | D2: anant@example.com | E2: MCH-001 | F2: Mechanical | G2: เสียงดังที่ชุดเพลาและแรงดันตก | H2: Critical | I2: TRUE | K2: Closed | L2: TECH-001 | M2: 46152.337 | N2: 46152.344 | O2: 46152.354 | P2: 46152.479 | Q2: 46152.51 | R2: 46152.521 | S2: 4 | T2: 46152.5 | U2: On Time | V2: 210 | W2: ลูกปืนเพลาสึกจากการหล่อลื่นไม่เพียงพอ | X2: เปลี่ยนลูกปืน ตั้งศูนย์เพลา และเติมจาระบี | Z2: 3 | AA2: 1050 | AB2: 640 | AC2: 1690 | AD2: TRUE | AE2: 5 | AF2: FALSE | AG2: 46152.521 | AH2: ข้อมูลตัวอย่าง
A3: WO-2026-0002 | B3: 46160.583 | C3: กมล ฝ่ายบรรจุ | D3: kamon@example.com | E3: MCH-002 | F3: Mechanical | G3: สายพานวิ่งเบี้ยวและสะบัด | H3: High | I3: TRUE | K3: Closed | L3: TECH-001 | M3: 46160.587 | N3: 46160.594 | O3: 46160.604 | P3: 46160.667 | Q3: 46160.698 | R3: 46160.708 | S3: 8 | T3: 46160.917 | U3: On Time | V3: 120 | W3: ลูกกลิ้งนำสายพานคลายตัว | X3: ตั้งแนวลูกกลิ้งและปรับความตึงสายพาน | Z3: 1.5 | AA3: 525 | AB3: 380 | AC3: 905 | AD3: TRUE | AE3: 4 | AF3: FALSE | AG3: 46160.708 | AH3: ข้อมูลตัวอย่าง
A4: WO-2026-0003 | B4: 46175.312 | C4: สุรีย์ ฝ่ายวิศวกรรม | D4: suree@example.com | E4: MCH-003 | F4: Pneumatic | G4: แรงดันลมตกและคอมเพรสเซอร์ทำงานต่อเนื่อง | H4: Critical | I4: TRUE | K4: Closed | L4: TECH-003 | M4: 46175.316 | N4: 46175.323 | O4: 46175.333 | P4: 46175.5 | Q4: 46175.531 | R4: 46175.542 | S4: 4 | T4: 46175.479 | U4: Late | V4: 300 | W4: โซลินอยด์วาล์วรั่วภายใน | X4: เปลี่ยนวาล์วและทดสอบการรั่ว | Z4: 4 | AA4: 1440 | AB4: 1250 | AC4: 2690 | AD4: TRUE | AE4: 5 | AF4: FALSE | AG4: 46175.542 | AH4: ข้อมูลตัวอย่าง
A5: WO-2026-0004 | B5: 46193.417 | C5: อนันต์ ฝ่ายผลิต | D5: anant@example.com | E5: MCH-004 | F5: Electrical | G5: ฮีตเตอร์ไม่ร้อน อุณหภูมิไม่ขึ้น | H5: High | I5: TRUE | K5: Closed | L5: TECH-002 | M5: 46193.42 | N5: 46193.427 | O5: 46193.438 | P5: 46193.521 | Q5: 46193.552 | R5: 46193.562 | S5: 8 | T5: 46193.75 | U5: On Time | V5: 150 | W5: ฟิวส์ฮีตเตอร์ขาดจากขั้วต่อหลวม | X5: เปลี่ยนฟิวส์และขันขั้วต่อ | Z5: 2 | AA5: 760 | AB5: 70 | AC5: 830 | AD5: TRUE | AE5: 4 | AF5: FALSE | AG5: 46193.562 | AH5: ข้อมูลตัวอย่าง
A6: WO-2026-0005 | B6: 46204.375 | C6: กมล ฝ่ายบรรจุ | D6: kamon@example.com | E6: MCH-001 | F6: Hydraulic | G6: น้ำมันไฮดรอลิกรั่วบริเวณวาล์ว | H6: High | I6: TRUE | K6: Closed | L6: TECH-002 | M6: 46204.378 | N6: 46204.385 | O6: 46204.396 | P6: 46204.5 | Q6: 46204.531 | R6: 46204.542 | S6: 8 | T6: 46204.708 | U6: On Time | V6: 180 | W6: โอริงวาล์วเสื่อมจากความร้อน | X6: เปลี่ยนซีล ทำความสะอาด และเติมน้ำมัน | Z6: 2.5 | AA6: 950 | AB6: 475 | AC6: 1425 | AD6: TRUE | AE6: 4 | AF6: FALSE | AG6: 46204.542 | AH6: ข้อมูลตัวอย่าง
A7: WO-2026-0006 | B7: 46218.542 | C7: สุรีย์ ฝ่ายวิศวกรรม | D7: suree@example.com | E7: MCH-005 | F7: Mechanical | G7: ปั๊มสั่นและมีเสียงผิดปกติ | H7: High | I7: TRUE | K7: Closed | L7: TECH-001 | M7: 46218.545 | N7: 46218.552 | O7: 46218.562 | P7: 46218.708 | Q7: 46218.74 | R7: 46218.75 | S7: 8 | T7: 46218.875 | U7: On Time | V7: 240 | W7: Mechanical seal เสื่อมและเพลาเยื้องศูนย์ | X7: เปลี่ยนซีลและตั้งศูนย์เพลา | Z7: 3.5 | AA7: 1225 | AB7: 2250 | AC7: 3475 | AD7: TRUE | AE7: 5 | AF7: FALSE | AG7: 46218.75 | AH7: ข้อมูลตัวอย่าง
A8: WO-2026-0007 | B8: 46237.354 | C8: อนันต์ ฝ่ายผลิต | D8: anant@example.com | E8: MCH-002 | F8: Automation | G8: เซนเซอร์ตรวจชิ้นงานทำงานไม่สม่ำเสมอ | H8: Medium | I8: FALSE | K8: Closed | L8: TECH-004 | M8: 46237.358 | N8: 46237.365 | O8: 46237.375 | P8: 46237.427 | Q8: 46237.458 | R8: 46237.469 | S8: 24 | T8: 46238.354 | U8: On Time | V8: 0 | W8: หน้าสัมผัสเซนเซอร์สกปรกและระยะคลาดเคลื่อน | X8: เปลี่ยนเซนเซอร์และตั้งระยะ | Z8: 1.25 | AA8: 525 | AB8: 890 | AC8: 1415 | AD8: TRUE | AE8: 4 | AF8: FALSE | AG8: 46237.469 | AH8: ข้อมูลตัวอย่าง
A9: WO-2026-0008 | B9: 46251.281 | C9: กมล ฝ่ายบรรจุ | D9: kamon@example.com | E9: MCH-003 | F9: Mechanical | G9: อุณหภูมิสูงและอัตราลมลดลง | H9: High | I9: TRUE | K9: Closed | L9: TECH-003 | M9: 46251.285 | N9: 46251.292 | O9: 46251.302 | P9: 46251.427 | Q9: 46251.458 | R9: 46251.469 | S9: 8 | T9: 46251.615 | U9: On Time | V9: 210 | W9: ไส้กรองอากาศอุดตัน | X9: เปลี่ยนไส้กรองและทำความสะอาดทางลม | Z9: 3 | AA9: 1080 | AB9: 650 | AC9: 1730 | AD9: TRUE | AE9: 5 | AF9: FALSE | AG9: 46251.469 | AH9: ข้อมูลตัวอย่าง
A10: WO-2026-0009 | B10: 46270.625 | C10: สุรีย์ ฝ่ายวิศวกรรม | D10: suree@example.com | E10: MCH-001 | F10: Mechanical | G10: แรงกดไม่คงที่ระหว่างรอบผลิต | H10: Critical | I10: TRUE | K10: Closed | L10: TECH-001 | M10: 46270.628 | N10: 46270.635 | O10: 46270.646 | P10: 46270.854 | Q10: 46270.885 | R10: 46270.896 | S10: 4 | T10: 46270.792 | U10: Late | V10: 360 | W10: น้ำมันเสื่อมและมีสิ่งปนเปื้อนในระบบ | X10: ถ่ายน้ำมัน ล้างระบบ และปรับแรงดัน | Z10: 5 | AA10: 1750 | AB10: 1900 | AC10: 3650 | AD10: TRUE | AE10: 4 | AF10: FALSE | AG10: 46270.896 | AH10: ข้อมูลตัวอย่าง
A11: WO-2026-0010 | B11: 46287.469 | C11: อนันต์ ฝ่ายผลิต | D11: anant@example.com | E11: MCH-004 | F11: Quality | G11: รอยซีลไม่สม่ำเสมอ | H11: Medium | I11: FALSE | K11: Closed | L11: TECH-004 | M11: 46287.472 | N11: 46287.479 | O11: 46287.49 | P11: 46287.562 | Q11: 46287.594 | R11: 46287.604 | S11: 24 | T11: 46288.469 | U11: On Time | V11: 0 | W11: เซนเซอร์วัดตำแหน่งตอบสนองช้า | X11: เปลี่ยนเซนเซอร์และปรับเทียบชุดควบคุม | Z11: 1.75 | AA11: 735 | AB11: 890 | AC11: 1625 | AD11: TRUE | AE11: 4 | AF11: FALSE | AG11: 46287.604 | AH11: ข้อมูลตัวอย่าง
A12: WO-2026-0011 | B12: 46299.333 | C12: กมล ฝ่ายบรรจุ | D12: kamon@example.com | E12: MCH-002 | F12: Mechanical | G12: สายพานมีรอยแตกร้าว | H12: High | I12: TRUE | K12: Closed | L12: TECH-001 | M12: 46299.337 | N12: 46299.344 | O12: 46299.354 | P12: 46299.438 | Q12: 46299.469 | R12: 46299.479 | S12: 8 | T12: 46299.667 | U12: On Time | V12: 150 | W12: สายพานครบอายุและความตึงไม่สม่ำเสมอ | X12: เปลี่ยนสายพานและตั้งความตึง | Z12: 2 | AA12: 700 | AB12: 380 | AC12: 1080 | AD12: TRUE | AE12: 5 | AF12: FALSE | AG12: 46299.479 | AH12: ข้อมูลตัวอย่าง
A13: WO-2026-0012 | B13: 46307.292 | C13: สุรีย์ ฝ่ายวิศวกรรม | D13: suree@example.com | E13: MCH-003 | F13: Pneumatic | G13: วาล์วระบายไม่ทำงาน | H13: Critical | I13: TRUE | K13: Closed | L13: TECH-003 | M13: 46307.295 | N13: 46307.302 | O13: 46307.312 | P13: 46307.5 | Q13: 46307.531 | R13: 46307.542 | S13: 4 | T13: 46307.458 | U13: Late | V13: 330 | W13: ขดลวดโซลินอยด์ไหม้จากแรงดันไฟเกิน | X13: เปลี่ยนโซลินอยด์และตรวจระบบไฟ | Z13: 4.5 | AA13: 1620 | AB13: 1285 | AC13: 2905 | AD13: TRUE | AE13: 5 | AF13: FALSE | AG13: 46307.542 | AH13: ข้อมูลตัวอย่าง
A14: WO-2026-0013 | B14: 46318.344 | C14: อนันต์ ฝ่ายผลิต | D14: anant@example.com | E14: MCH-006 | F14: Software | G14: โปรแกรม CNC แจ้งเตือน Axis overload | H14: High | I14: FALSE | K14: New | S14: 8 | T14: 46318.677 | U14: Within SLA | V14: 0 | Z14: 0 | AA14: 0 | AB14: 0 | AC14: 0 | AD14: FALSE | AF14: FALSE | AG14: 46318.479 | AH14: รอหัวหน้ามอบหมาย
A15: WO-2026-0014 | B15: 46318.319 | C15: กมล ฝ่ายบรรจุ | D15: kamon@example.com | E15: MCH-001 | F15: Hydraulic | G15: พบคราบน้ำมันใต้ชุดวาล์ว | H15: High | I15: FALSE | K15: Assigned | L15: TECH-001 | M15: 46318.326 | S15: 8 | T15: 46318.653 | U15: Within SLA | V15: 0 | Z15: 0 | AA15: 0 | AB15: 0 | AC15: 0 | AD15: FALSE | AF15: FALSE | AG15: 46318.479 | AH15: นัดตรวจช่วงพักสายการผลิต
A16: WO-2026-0015 | B16: 46317.764 | C16: สุรีย์ ฝ่ายวิศวกรรม | D16: suree@example.com | E16: MCH-005 | F16: Mechanical | G16: ปั๊มสั่นสูงกว่าค่ามาตรฐาน | H16: Critical | I16: TRUE | K16: In Progress | L16: TECH-001 | M16: 46317.771 | N16: 46317.781 | O16: 46317.792 | S16: 4 | T16: 46317.931 | U16: Overdue | V16: 1020 | W16: อยู่ระหว่างตรวจสอบแนวเพลา | X16: ตรวจ vibration และ alignment | Z16: 17 | AA16: 5950 | AB16: 0 | AC16: 5950 | AD16: FALSE | AF16: FALSE | AG16: 46318.479 | AH16: กำลังดำเนินการ
A17: WO-2026-0016 | B17: 46317.417 | C17: อนันต์ ฝ่ายผลิต | D17: anant@example.com | E17: MCH-004 | F17: Electrical | G17: ชุดควบคุมอุณหภูมิตัดเป็นช่วง | H17: Medium | I17: FALSE | K17: Waiting Parts | L17: TECH-002 | M17: 46317.424 | N17: 46317.434 | O17: 46317.444 | S17: 24 | T17: 46318.417 | U17: Overdue | V17: 0 | W17: รีเลย์ควบคุมหน้าสัมผัสเสื่อม | X17: รออะไหล่รีเลย์ | Z17: 25.33 | AA17: 9625.4 | AB17: 0 | AC17: 9625.4 | AD17: FALSE | AF17: FALSE | AG17: 46318.479 | AH17: อะไหล่กำหนดถึง 24 ต.ค.

Sheet Assignments
A1: AssignmentID | B1: WorkOrderID | C1: TechnicianID | D1: AssignmentRole | E1: AssignedAt | F1: AcceptedAt | G1: StartedAt | H1: FinishedAt | I1: AssignmentStatus | J1: WorkHours | K1: Notes
A2: ASN-0001 | B2: WO-2026-0001 | C2: TECH-001 | D2: Lead | E2: 46152.337 | F2: 46152.344 | G2: 46152.354 | H2: 46152.479 | I2: Finished | J2: 3
A3: ASN-0002 | B3: WO-2026-0002 | C3: TECH-001 | D3: Lead | E3: 46160.587 | F3: 46160.594 | G3: 46160.604 | H3: 46160.667 | I3: Finished | J3: 1.5
A4: ASN-0003 | B4: WO-2026-0003 | C4: TECH-003 | D4: Lead | E4: 46175.316 | F4: 46175.323 | G4: 46175.333 | H4: 46175.5 | I4: Finished | J4: 4
A5: ASN-0004 | B5: WO-2026-0004 | C5: TECH-002 | D5: Lead | E5: 46193.42 | F5: 46193.427 | G5: 46193.438 | H5: 46193.521 | I5: Finished | J5: 2
A6: ASN-0005 | B6: WO-2026-0005 | C6: TECH-002 | D6: Lead | E6: 46204.378 | F6: 46204.385 | G6: 46204.396 | H6: 46204.5 | I6: Finished | J6: 2.5
A7: ASN-0006 | B7: WO-2026-0006 | C7: TECH-001 | D7: Lead | E7: 46218.545 | F7: 46218.552 | G7: 46218.562 | H7: 46218.708 | I7: Finished | J7: 3.5
A8: ASN-0007 | B8: WO-2026-0007 | C8: TECH-004 | D8: Lead | E8: 46237.358 | F8: 46237.365 | G8: 46237.375 | H8: 46237.427 | I8: Finished | J8: 1.25
A9: ASN-0008 | B9: WO-2026-0008 | C9: TECH-003 | D9: Lead | E9: 46251.285 | F9: 46251.292 | G9: 46251.302 | H9: 46251.427 | I9: Finished | J9: 3
A10: ASN-0009 | B10: WO-2026-0009 | C10: TECH-001 | D10: Lead | E10: 46270.628 | F10: 46270.635 | G10: 46270.646 | H10: 46270.854 | I10: Finished | J10: 5
A11: ASN-0009-B | B11: WO-2026-0009 | C11: TECH-002 | D11: Assistant | E11: 46270.649 | F11: 46270.646 | G11: 46270.646 | H11: 46270.854 | I11: Finished | J11: 2.5 | K11: ช่วยตรวจระบบไฟ/ควบคุม
A12: ASN-0010 | B12: WO-2026-0010 | C12: TECH-004 | D12: Lead | E12: 46287.472 | F12: 46287.479 | G12: 46287.49 | H12: 46287.562 | I12: Finished | J12: 1.75
A13: ASN-0011 | B13: WO-2026-0011 | C13: TECH-001 | D13: Lead | E13: 46299.337 | F13: 46299.344 | G13: 46299.354 | H13: 46299.438 | I13: Finished | J13: 2
A14: ASN-0012 | B14: WO-2026-0012 | C14: TECH-003 | D14: Lead | E14: 46307.295 | F14: 46307.302 | G14: 46307.312 | H14: 46307.5 | I14: Finished | J14: 4.5
A15: ASN-0012-B | B15: WO-2026-0012 | C15: TECH-004 | D15: Assistant | E15: 46307.316 | F15: 46307.312 | G15: 46307.312 | H15: 46307.5 | I15: Finished | J15: 2.25 | K15: ช่วยตรวจระบบไฟ/ควบคุม
A16: ASN-0014 | B16: WO-2026-0014 | C16: TECH-001 | D16: Lead | E16: 46318.326 | I16: Assigned | J16: 0 | K16: นัดตรวจช่วงพักสายการผลิต
A17: ASN-0015 | B17: WO-2026-0015 | C17: TECH-001 | D17: Lead | E17: 46317.771 | F17: 46317.781 | G17: 46317.792 | I17: Working | J17: 17 | K17: กำลังดำเนินการ
A18: ASN-0016 | B18: WO-2026-0016 | C18: TECH-002 | D18: Lead | E18: 46317.424 | F18: 46317.434 | G18: 46317.444 | I18: Paused | J18: 25.33 | K18: อะไหล่กำหนดถึง 24 ต.ค.

Sheet RepairHistory
A1: RepairHistoryID | B1: WorkOrderID | C1: MachineID | D1: TechnicianID | E1: FailureStart | F1: RepairStart | G1: RepairEnd | H1: ReturnedToService | I1: FailureMode | J1: RootCause | K1: RepairAction | L1: DowntimeMinutes | M1: RepairMinutes | N1: FailureIntervalHours | O1: LaborCost | P1: PartsCost | Q1: TotalCost | R1: ClosedByEmail | S1: ClosedAt | T1: Notes
A2: RH-0001 | B2: WO-2026-0001 | C2: MCH-001 | D2: TECH-001 | E2: 46152.333 | F2: 46152.354 | G2: 46152.479 | H2: 46152.479 | I2: Bearing wear | J2: ลูกปืนเพลาสึกจากการหล่อลื่นไม่เพียงพอ | K2: เปลี่ยนลูกปืน ตั้งศูนย์เพลา และเติมจาระบี | L2: 210 | M2: 180 | O2: 1050 | P2: 640 | Q2: 1690 | R2: kitti@example.com | S2: 46152.521 | T2: ข้อมูลตัวอย่าง
A3: RH-0002 | B3: WO-2026-0002 | C3: MCH-002 | D3: TECH-001 | E3: 46160.583 | F3: 46160.604 | G3: 46160.667 | H3: 46160.667 | I3: Belt misalignment | J3: ลูกกลิ้งนำสายพานคลายตัว | K3: ตั้งแนวลูกกลิ้งและปรับความตึงสายพาน | L3: 120 | M3: 90 | O3: 525 | P3: 380 | Q3: 905 | R3: kitti@example.com | S3: 46160.708 | T3: ข้อมูลตัวอย่าง
A4: RH-0003 | B4: WO-2026-0003 | C4: MCH-003 | D4: TECH-003 | E4: 46175.312 | F4: 46175.333 | G4: 46175.5 | H4: 46175.521 | I4: Air valve leak | J4: โซลินอยด์วาล์วรั่วภายใน | K4: เปลี่ยนวาล์วและทดสอบการรั่ว | L4: 300 | M4: 240 | O4: 1440 | P4: 1250 | Q4: 2690 | R4: kitti@example.com | S4: 46175.542 | T4: ข้อมูลตัวอย่าง
A5: RH-0004 | B5: WO-2026-0004 | C5: MCH-004 | D5: TECH-002 | E5: 46193.417 | F5: 46193.438 | G5: 46193.521 | H5: 46193.521 | I5: Heater circuit open | J5: ฟิวส์ฮีตเตอร์ขาดจากขั้วต่อหลวม | K5: เปลี่ยนฟิวส์และขันขั้วต่อ | L5: 150 | M5: 120 | O5: 760 | P5: 70 | Q5: 830 | R5: kitti@example.com | S5: 46193.562 | T5: ข้อมูลตัวอย่าง
A6: RH-0005 | B6: WO-2026-0005 | C6: MCH-001 | D6: TECH-002 | E6: 46204.375 | F6: 46204.396 | G6: 46204.5 | H6: 46204.5 | I6: Hydraulic leak | J6: โอริงวาล์วเสื่อมจากความร้อน | K6: เปลี่ยนซีล ทำความสะอาด และเติมน้ำมัน | L6: 180 | M6: 150 | N6: 1245.5 | O6: 950 | P6: 475 | Q6: 1425 | R6: kitti@example.com | S6: 46204.542 | T6: ข้อมูลตัวอย่าง
A7: RH-0006 | B7: WO-2026-0006 | C7: MCH-005 | D7: TECH-001 | E7: 46218.542 | F7: 46218.562 | G7: 46218.708 | H7: 46218.708 | I7: Seal degradation | J7: Mechanical seal เสื่อมและเพลาเยื้องศูนย์ | K7: เปลี่ยนซีลและตั้งศูนย์เพลา | L7: 240 | M7: 210 | O7: 1225 | P7: 2250 | Q7: 3475 | R7: kitti@example.com | S7: 46218.75 | T7: ข้อมูลตัวอย่าง
A8: RH-0007 | B8: WO-2026-0007 | C8: MCH-002 | D8: TECH-004 | E8: 46237.354 | F8: 46237.375 | G8: 46237.427 | H8: 46237.427 | I8: Sensor drift | J8: หน้าสัมผัสเซนเซอร์สกปรกและระยะคลาดเคลื่อน | K8: เปลี่ยนเซนเซอร์และตั้งระยะ | L8: 0 | M8: 75 | N8: 1840.5 | O8: 525 | P8: 890 | Q8: 1415 | R8: kitti@example.com | S8: 46237.469 | T8: ข้อมูลตัวอย่าง
A9: RH-0008 | B9: WO-2026-0008 | C9: MCH-003 | D9: TECH-003 | E9: 46251.281 | F9: 46251.302 | G9: 46251.427 | H9: 46251.427 | I9: Filter restriction | J9: ไส้กรองอากาศอุดตัน | K9: เปลี่ยนไส้กรองและทำความสะอาดทางลม | L9: 210 | M9: 180 | N9: 1818.25 | O9: 1080 | P9: 650 | Q9: 1730 | R9: kitti@example.com | S9: 46251.469 | T9: ข้อมูลตัวอย่าง
A10: RH-0009 | B10: WO-2026-0009 | C10: MCH-001 | D10: TECH-001 | E10: 46270.625 | F10: 46270.646 | G10: 46270.854 | H10: 46270.875 | I10: Pump efficiency loss | J10: น้ำมันเสื่อมและมีสิ่งปนเปื้อนในระบบ | K10: ถ่ายน้ำมัน ล้างระบบ และปรับแรงดัน | L10: 360 | M10: 300 | N10: 1587 | O10: 1750 | P10: 1900 | Q10: 3650 | R10: kitti@example.com | S10: 46270.896 | T10: ข้อมูลตัวอย่าง
A11: RH-0010 | B11: WO-2026-0010 | C11: MCH-004 | D11: TECH-004 | E11: 46287.469 | F11: 46287.49 | G11: 46287.562 | H11: 46287.562 | I11: Temperature control drift | J11: เซนเซอร์วัดตำแหน่งตอบสนองช้า | K11: เปลี่ยนเซนเซอร์และปรับเทียบชุดควบคุม | L11: 0 | M11: 105 | N11: 2254.75 | O11: 735 | P11: 890 | Q11: 1625 | R11: kitti@example.com | S11: 46287.604 | T11: ข้อมูลตัวอย่าง
A12: RH-0011 | B12: WO-2026-0011 | C12: MCH-002 | D12: TECH-001 | E12: 46299.333 | F12: 46299.354 | G12: 46299.438 | H12: 46299.438 | I12: Belt fatigue | J12: สายพานครบอายุและความตึงไม่สม่ำเสมอ | K12: เปลี่ยนสายพานและตั้งความตึง | L12: 150 | M12: 120 | N12: 1485.75 | O12: 700 | P12: 380 | Q12: 1080 | R12: kitti@example.com | S12: 46299.479 | T12: ข้อมูลตัวอย่าง
A13: RH-0012 | B13: WO-2026-0012 | C13: MCH-003 | D13: TECH-003 | E13: 46307.292 | F13: 46307.312 | G13: 46307.5 | H13: 46307.521 | I13: Solenoid failure | J13: ขดลวดโซลินอยด์ไหม้จากแรงดันไฟเกิน | K13: เปลี่ยนโซลินอยด์และตรวจระบบไฟ | L13: 330 | M13: 270 | N13: 1340.75 | O13: 1620 | P13: 1285 | Q13: 2905 | R13: kitti@example.com | S13: 46307.542 | T13: ข้อมูลตัวอย่าง

Sheet Parts
A1: PartID | B1: PartCode | C1: PartNameTH | D1: Category | E1: Unit | F1: StockQty | G1: ReorderPoint | H1: UnitCost | I1: Supplier | J1: StorageLocation | K1: Active | L1: Notes
A2: PRT-001 | B2: BRG-6205 | C2: ลูกปืน 6205 | D2: Bearing | E2: ชิ้น | F2: 12 | G2: 4 | H2: 450 | I2: Bearing Center | J2: A-01 | K2: TRUE
A3: PRT-002 | B3: BLT-A52 | C3: สายพาน A52 | D3: Belt | E3: เส้น | F3: 6 | G3: 2 | H3: 380 | I3: Belt Supply | J3: A-02 | K3: TRUE
A4: PRT-003 | B4: SOL-24V | C4: โซลินอยด์วาล์ว 24V | D4: Valve | E4: ชิ้น | F4: 3 | G4: 2 | H4: 1250 | I4: Automation Shop | J4: B-01 | K4: TRUE
A5: PRT-004 | B5: OIL-H68 | C5: น้ำมันไฮดรอลิก ISO VG 68 | D5: Lubricant | E5: ลิตร | F5: 80 | G5: 30 | H5: 95 | I5: Industrial Oil | J5: C-01 | K5: TRUE
A6: PRT-005 | B6: SNS-PROX | C6: Proximity Sensor M18 | D6: Sensor | E6: ชิ้น | F6: 5 | G6: 2 | H6: 890 | I6: Automation Shop | J6: B-02 | K6: TRUE
A7: PRT-006 | B7: FUSE-10A | C7: ฟิวส์ 10A | D7: Electrical | E7: ชิ้น | F7: 30 | G7: 10 | H7: 35 | I7: Electrical Store | J7: D-01 | K7: TRUE
A8: PRT-007 | B8: SEAL-40 | C8: Mechanical Seal 40 mm | D8: Seal | E8: ชุด | F8: 1 | G8: 2 | H8: 1800 | I8: Pump Parts | J8: A-03 | K8: TRUE | L8: ต่ำกว่าจุดสั่งซื้อ
A9: PRT-008 | B9: FLT-AIR | C9: ไส้กรองอากาศ | D9: Filter | E9: ชิ้น | F9: 4 | G9: 2 | H9: 650 | I9: AirPro Service | J9: C-03 | K9: TRUE

Sheet PartUsage
A1: PartUsageID | B1: WorkOrderID | C1: PartID | D1: Quantity | E1: UnitCost | F1: LineTotal | G1: UsedByTechnicianID | H1: UsedAt | I1: Notes
A2: USE-0001-1 | B2: WO-2026-0001 | C2: PRT-001 | D2: 1 | E2: 450 | F2: 450 | G2: TECH-001 | H2: 46152.465
A3: USE-0001-2 | B3: WO-2026-0001 | C3: PRT-004 | D3: 2 | E3: 95 | F3: 190 | G3: TECH-001 | H3: 46152.465
A4: USE-0002-1 | B4: WO-2026-0002 | C4: PRT-002 | D4: 1 | E4: 380 | F4: 380 | G4: TECH-001 | H4: 46160.653
A5: USE-0003-1 | B5: WO-2026-0003 | C5: PRT-003 | D5: 1 | E5: 1250 | F5: 1250 | G5: TECH-003 | H5: 46175.486
A6: USE-0004-1 | B6: WO-2026-0004 | C6: PRT-006 | D6: 2 | E6: 35 | F6: 70 | G6: TECH-002 | H6: 46193.507
A7: USE-0005-1 | B7: WO-2026-0005 | C7: PRT-004 | D7: 5 | E7: 95 | F7: 475 | G7: TECH-002 | H7: 46204.486
A8: USE-0006-1 | B8: WO-2026-0006 | C8: PRT-007 | D8: 1 | E8: 1800 | F8: 1800 | G8: TECH-001 | H8: 46218.694
A9: USE-0006-2 | B9: WO-2026-0006 | C9: PRT-001 | D9: 1 | E9: 450 | F9: 450 | G9: TECH-001 | H9: 46218.694
A10: USE-0007-1 | B10: WO-2026-0007 | C10: PRT-005 | D10: 1 | E10: 890 | F10: 890 | G10: TECH-004 | H10: 46237.413
A11: USE-0008-1 | B11: WO-2026-0008 | C11: PRT-008 | D11: 1 | E11: 650 | F11: 650 | G11: TECH-003 | H11: 46251.413
A12: USE-0009-1 | B12: WO-2026-0009 | C12: PRT-004 | D12: 20 | E12: 95 | F12: 1900 | G12: TECH-001 | H12: 46270.84
A13: USE-0010-1 | B13: WO-2026-0010 | C13: PRT-005 | D13: 1 | E13: 890 | F13: 890 | G13: TECH-004 | H13: 46287.549
... A16: USE-0012-2 | B16: WO-2026-0012 | C16: PRT-006 | D16: 1 | E16: 35 | F16: 35 | G16: TECH-003 | H16: 46307.486

Sheet StatusLog
A1: StatusLogID | B1: WorkOrderID | C1: ChangedAt | D1: FromStatus | E1: ToStatus | F1: ChangedByEmail | G1: Comment
A2: STL-0001-1 | B2: WO-2026-0001 | C2: 46152.333 | E2: New | F2: anant@example.com | G2: สร้างใบงาน
A3: STL-0001-2 | B3: WO-2026-0001 | C3: 46152.337 | D3: New | E3: Assigned | F3: kitti@example.com | G3: เปลี่ยนสถานะเป็น Assigned
A4: STL-0001-3 | B4: WO-2026-0001 | C4: 46152.344 | D4: Assigned | E4: Accepted | F4: somchai@example.com | G4: เปลี่ยนสถานะเป็น Accepted
A5: STL-0001-4 | B5: WO-2026-0001 | C5: 46152.354 | D5: Accepted | E5: In Progress | F5: somchai@example.com | G5: เปลี่ยนสถานะเป็น In Progress
A6: STL-0001-5 | B6: WO-2026-0001 | C6: 46152.479 | D6: In Progress | E6: Completed | F6: somchai@example.com | G6: เปลี่ยนสถานะเป็น Completed
A7: STL-0001-6 | B7: WO-2026-0001 | C7: 46152.51 | D7: Completed | E7: Verified | F7: anant@example.com | G7: เปลี่ยนสถานะเป็น Verified
A8: STL-0001-7 | B8: WO-2026-0001 | C8: 46152.521 | D8: Verified | E8: Closed | F8: kitti@example.com | G8: เปลี่ยนสถานะเป็น Closed
A9: STL-0002-1 | B9: WO-2026-0002 | C9: 46160.583 | E9: New | F9: kamon@example.com | G9: สร้างใบงาน
A10: STL-0002-2 | B10: WO-2026-0002 | C10: 46160.587 | D10: New | E10: Assigned | F10: kitti@example.com | G10: เปลี่ยนสถานะเป็น Assigned
A11: STL-0002-3 | B11: WO-2026-0002 | C11: 46160.594 | D11: Assigned | E11: Accepted | F11: somchai@example.com | G11: เปลี่ยนสถานะเป็น Accepted
A12: STL-0002-4 | B12: WO-2026-0002 | C12: 46160.604 | D12: Accepted | E12: In Progress | F12: somchai@example.com | G12: เปลี่ยนสถานะเป็น In Progress
A13: STL-0002-5 | B13: WO-2026-0002 | C13: 46160.667 | D13: In Progress | E13: Completed | F13: somchai@example.com | G13: เปลี่ยนสถานะเป็น Completed
A14: STL-0002-6 | B14: WO-2026-0002 | C14: 46160.698 | D14: Completed | E14: Verified | F14: kamon@example.com | G14: เปลี่ยนสถานะเป็น Verified
A15: STL-0002-7 | B15: WO-2026-0002 | C15: 46160.708 | D15: Verified | E15: Closed | F15: kitti@example.com | G15: เปลี่ยนสถานะเป็น Closed
A16: STL-0003-1 | B16: WO-2026-0003 | C16: 46175.312 | E16: New | F16: suree@example.com | G16: สร้างใบงาน
A17: STL-0003-2 | B17: WO-2026-0003 | C17: 46175.316 | D17: New | E17: Assigned | F17: kitti@example.com | G17: เปลี่ยนสถานะเป็น Assigned
A18: STL-0003-3 | B18: WO-2026-0003 | C18: 46175.323 | D18: Assigned | E18: Accepted | F18: wichai@example.com | G18: เปลี่ยนสถานะเป็น Accepted
A19: STL-0003-4 | B19: WO-2026-0003 | C19: 46175.333 | D19: Accepted | E19: In Progress | F19: wichai@example.com | G19: เปลี่ยนสถานะเป็น In Progress
A20: STL-0003-5 | B20: WO-2026-0003 | C20: 46175.5 | D20: In Progress | E20: Completed | F20: wichai@example.com | G20: เปลี่ยนสถานะเป็น Completed
A21: STL-0003-6 | B21: WO-2026-0003 | C21: 46175.531 | D21: Completed | E21: Verified | F21: suree@example.com | G21: เปลี่ยนสถานะเป็น Verified
A22: STL-0003-7 | B22: WO-2026-0003 | C22: 46175.542 | D22: Verified | E22: Closed | F22: kitti@example.com | G22: เปลี่ยนสถานะเป็น Closed
A23: STL-0004-1 | B23: WO-2026-0004 | C23: 46193.417 | E23: New | F23: anant@example.com | G23: สร้างใบงาน
A24: STL-0004-2 | B24: WO-2026-0004 | C24: 46193.42 | D24: New | E24: Assigned | F24: kitti@example.com | G24: เปลี่ยนสถานะเป็น Assigned
A25: STL-0004-3 | B25: WO-2026-0004 | C25: 46193.427 | D25: Assigned | E25: Accepted | F25: somying@example.com | G25: เปลี่ยนสถานะเป็น Accepted
A26: STL-0004-4 | B26: WO-2026-0004 | C26: 46193.438 | D26: Accepted | E26: In Progress | F26: somying@example.com | G26: เปลี่ยนสถานะเป็น In Progress
A27: STL-0004-5 | B27: WO-2026-0004 | C27: 46193.521 | D27: In Progress | E27: Completed | F27: somying@example.com | G27: เปลี่ยนสถานะเป็น Completed
A28: STL-0004-6 | B28: WO-2026-0004 | C28: 46193.552 | D28: Completed | E28: Verified | F28: anant@example.com | G28: เปลี่ยนสถานะเป็น Verified
A29: STL-0004-7 | B29: WO-2026-0004 | C29: 46193.562 | D29: Verified | E29: Closed | F29: kitti@example.com | G29: เปลี่ยนสถานะเป็น Closed
A30: STL-0005-1 | B30: WO-2026-0005 | C30: 46204.375 | E30: New | F30: kamon@example.com | G30: สร้างใบงาน
A31: STL-0005-2 | B31: WO-2026-0005 | C31: 46204.378 | D31: New | E31: Assigned | F31: kitti@example.com | G31: เปลี่ยนสถานะเป็น Assigned
A32: STL-0005-3 | B32: WO-2026-0005 | C32: 46204.385 | D32: Assigned | E32: Accepted | F32: somying@example.com | G32: เปลี่ยนสถานะเป็น Accepted
A33: STL-0005-4 | B33: WO-2026-0005 | C33: 46204.396 | D33: Accepted | E33: In Progress | F33: somying@example.com | G33: เปลี่ยนสถานะเป็น In Progress
A34: STL-0005-5 | B34: WO-2026-0005 | C34: 46204.5 | D34: In Progress | E34: Completed | F34: somying@example.com | G34: เปลี่ยนสถานะเป็น Completed
A35: STL-0005-6 | B35: WO-2026-0005 | C35: 46204.531 | D35: Completed | E35: Verified | F35: kamon@example.com | G35: เปลี่ยนสถานะเป็น Verified
A36: STL-0005-7 | B36: WO-2026-0005 | C36: 46204.542 | D36: Verified | E36: Closed | F36: kitti@example.com | G36: เปลี่ยนสถานะเป็น Closed
A37: STL-0006-1 | B37: WO-2026-0006 | C37: 46218.542 | E37: New | F37: suree@example.com | G37: สร้างใบงาน
A38: STL-0006-2 | B38: WO-2026-0006 | C38: 46218.545 | D38: New | E38: Assigned | F38: kitti@example.com | G38: เปลี่ยนสถานะเป็น Assigned
A39: STL-0006-3 | B39: WO-2026-0006 | C39: 46218.552 | D39: Assigned | E39: Accepted | F39: somchai@example.com | G39: เปลี่ยนสถานะเป็น Accepted
A40: STL-0006-4 | B40: WO-2026-0006 | C40: 46218.562 | D40: Accepted | E40: In Progress | F40: somchai@example.com | G40: เปลี่ยนสถานะเป็น In Progress
...

Sheet Settings
A1: SettingID | B1: SettingType | C1: SettingValue | D1: SortOrder | E1: Active | F1: DescriptionTH
A2: SET-001 | B2: ProblemCategory | C2: Mechanical | D2: 1 | E2: TRUE
A3: SET-002 | B3: ProblemCategory | C3: Electrical | D3: 2 | E3: TRUE
A4: SET-003 | B4: ProblemCategory | C4: Hydraulic | D4: 3 | E4: TRUE
A5: SET-004 | B5: ProblemCategory | C5: Pneumatic | D5: 4 | E5: TRUE
A6: SET-005 | B6: ProblemCategory | C6: Automation | D6: 5 | E6: TRUE
A7: SET-006 | B7: ProblemCategory | C7: Software | D7: 6 | E7: TRUE
A8: SET-007 | B8: ProblemCategory | C8: Quality | D8: 7 | E8: TRUE
A9: SET-008 | B9: ProblemCategory | C9: Safety | D9: 8 | E9: TRUE
A10: SET-009 | B10: ProblemCategory | C10: Other | D10: 9 | E10: TRUE
A11: SET-010 | B11: Priority | C11: Critical | D11: 1 | E11: TRUE
A12: SET-011 | B12: Priority | C12: High | D12: 2 | E12: TRUE
A13: SET-012 | B13: Priority | C13: Medium | D13: 3 | E13: TRUE
... A65: SET-064 | B65: Unit | C65: กิโลกรัม | D65: 6 | E65: TRUE

Sheet AppSheet_Config
A1: การตั้งค่า AppSheet
A2: คัดลอก Initial value, App formula และ Valid If ไปยัง Data → Columns ของ AppSheet
A3: Table | B3: Column | C3: คำอธิบายไทย | D3: Type | E3: Key | F3: Label | G3: Ref table | H3: Initial value | I3: App formula / Valid If | J3: หมายเหตุ
A4: Machines | B4: MachineID | C4: รหัสเครื่องภายใน | D4: Text | E4: Y | H4: UNIQUEID()
A5: Machines | B5: MachineCode | C5: รหัสเครื่องหน้างาน | D5: Text | F5: Y | J5: ใช้ทำ QR/Barcode
A6: Machines | B6: MachineNameTH | C6: ชื่อเครื่องจักร | D6: Name
A7: Machines | B7: Criticality | C7: ความสำคัญ | D7: Enum | I7: SELECT(Settings[SettingValue],AND([SettingType]="Criticality",[Active]=TRUE))
A8: Machines | B8: MachineStatus | C8: สถานะเครื่อง | D8: Enum | I8: SELECT(Settings[SettingValue],AND([SettingType]="MachineStatus",[Active]=TRUE))
A9: Machines | B9: Image | C9: รูปเครื่อง | D9: Image
A10: Machines | B10: Active | C10: ใช้งานอยู่ | D10: Yes/No | H10: TRUE
A11: Technicians | B11: TechnicianID | C11: รหัสช่าง | D11: Text | E11: Y | H11: UNIQUEID()
A12: Technicians | B12: FullNameTH | C12: ชื่อช่าง | D12: Name | F12: Y
A13: Technicians | B13: Email | C13: อีเมล | D13: Email | J13: ต้องตรงบัญชีผู้ใช้
A14: Technicians | B14: AppRole | C14: บทบาท | D14: Enum | I14: SELECT(Settings[SettingValue],AND([SettingType]="AppRole",[Active]=TRUE))
A15: WorkOrders | B15: WorkOrderID | C15: รหัสใบงาน | D15: Text | E15: Y | H15: UNIQUEID()
A16: WorkOrders | B16: RequestDateTime | C16: เวลาแจ้ง | D16: DateTime | H16: NOW()
A17: WorkOrders | B17: RequesterEmail | C17: ผู้แจ้ง | D17: Email | H17: USEREMAIL()
A18: WorkOrders | B18: MachineID | C18: เครื่องจักร | D18: Ref | G18: Machines | I18: SELECT(Machines[MachineID],[Active]=TRUE)
A19: WorkOrders | B19: Priority | C19: ความเร่งด่วน | D19: Enum | I19: SELECT(Settings[SettingValue],AND([SettingType]="Priority",[Active]=TRUE))
A20: WorkOrders | B20: WorkOrderStatus | C20: สถานะใบงาน | D20: Enum | H20: "New" | I20: SELECT(Settings[SettingValue],AND([SettingType]="WorkOrderStatus",[Active]=TRUE))
A21: WorkOrders | B21: PrimaryTechnicianID | C21: ช่างหลัก | D21: Ref | G21: Technicians | I21: SELECT(Technicians[TechnicianID],AND([Active]=TRUE,[AppRole]="Technician"))
A22: WorkOrders | B22: SLAHours | C22: SLA ชั่วโมง | D22: Number | I22: SWITCH([Priority],"Critical",4,"High",8,"Medium",24,"Low",72,24) | J22: App formula
A23: WorkOrders | B23: DueAt | C23: กำหนดตาม SLA | D23: DateTime | I23: [RequestDateTime]+([SLAHours]/24.0) | J23: App formula
A24: WorkOrders | B24: DowntimeMinutes | C24: เวลาหยุดเครื่อง | D24: Number | I24: IF(AND([MachineStopped],[StartedAt]<>""),ROUND(1440*(IF([CompletedAt]="",NOW(),[CompletedAt])-[StartedAt])),0) | J24: App formula
A25: WorkOrders | B25: LaborCost | C25: ค่าแรง | D25: Price | I25: [LaborHours]*[PrimaryTechnicianID].[HourlyRate] | J25: App formula
A26: WorkOrders | B26: PartsCost | C26: ค่าอะไหล่ | D26: Price | I26: SUM(SELECT(PartUsage[LineTotal],[WorkOrderID]=[_THISROW].[WorkOrderID])) | J26: App formula
A27: WorkOrders | B27: TotalCost | C27: ค่าใช้จ่ายรวม | D27: Price | I27: [LaborCost]+[PartsCost] | J27: App formula
A28: Assignments | B28: AssignmentID | C28: รหัสมอบหมาย | D28: Text | E28: Y | H28: UNIQUEID()
A29: Assignments | B29: WorkOrderID | C29: ใบงาน | D29: Ref | G29: WorkOrders | J29: เปิด Is a part of
A30: Assignments | B30: TechnicianID | C30: ช่าง | D30: Ref | G30: Technicians
A31: Assignments | B31: AcceptedAt | C31: เวลารับงาน | D31: DateTime | J31: ตั้งด้วย Action NOW()
A32: RepairHistory | B32: RepairHistoryID | C32: รหัสประวัติ | D32: Text | E32: Y | H32: UNIQUEID()
A33: RepairHistory | B33: WorkOrderID | C33: ใบงานต้นทาง | D33: Ref | G33: WorkOrders | J33: สร้างด้วย Bot เมื่อ Closed
A34: RepairHistory | B34: MachineID | C34: เครื่องจักร | D34: Ref | G34: Machines
A35: RepairHistory | B35: RepairMinutes | C35: เวลาซ่อมจริง | D35: Number | I35: ROUND(1440*([RepairEnd]-[RepairStart])) | J35: ใช้คำนวณ MTTR
A36: RepairHistory | B36: FailureIntervalHours | C36: ชั่วโมงระหว่างเสีย | D36: Decimal | I36: IF(ISBLANK(MAX(SELECT(RepairHistory[ReturnedToService],[MachineID]=[_THISROW].[MachineID]))),"",24*([FailureStart]-MAX(SELECT(RepairHistory[ReturnedToService],[MachineID]=[_THISROW].[MachineID])))) | J36: ใช้คำนวณ MTBF
A37: Parts | B37: PartID | C37: รหัสอะไหล่ | D37: Text | E37: Y | H37: UNIQUEID()
A38: Parts | B38: PartCode | C38: รหัสอะไหล่ | D38: Text | F38: Y
A39: PartUsage | B39: PartUsageID | C39: รหัสเบิก | D39: Text | E39: Y | H39: UNIQUEID()
A40: PartUsage | B40: WorkOrderID | C40: ใบงาน | D40: Ref | G40: WorkOrders | J40: เปิด Is a part of
...

Sheet Lists
A1: ProblemCategoryList | B1: PriorityList | C1: WorkOrderStatusList | D1: AssignmentRoleList | E1: AssignmentStatusList | F1: MachineStatusList | G1: CriticalityList | H1: SkillGroupList | I1: AppRoleList | J1: PartCategoryList | K1: UnitList | L1: BooleanList | M1: RatingList
A2: Mechanical | B2: Critical | C2: New | D2: Lead | E2: Assigned | F2: Running | G2: High | H2: Mechanical | I2: Admin | J2: Bearing | K2: ชิ้น | L2: TRUE | M2: 1
A3: Electrical | B3: High | C3: Assigned | D3: Assistant | E3: Accepted | F3: Standby | G3: Medium | H3: Electrical | I3: Manager | J3: Belt | K3: เส้น | L3: FALSE | M3: 2
A4: Hydraulic | B4: Medium | C4: Accepted | D4: Specialist | E4: Working | F4: Under Repair | G4: Low | H4: Hydraulic | I4: Technician | J4: Valve | K4: ลิตร | M4: 3
A5: Pneumatic | B5: Low | C5: In Progress | E5: Paused | F5: Out of Service | H5: Pneumatic | I5: Requester | J5: Lubricant | K5: ชุด | M5: 4
A6: Automation | C6: Waiting Parts | E6: Finished | H6: Automation | J6: Sensor | K6: เมตร | M6: 5
A7: Software | C7: Completed | E7: Cancelled | H7: Software | J7: Electrical | K7: กิโลกรัม
A8: Quality | C8: Verified | H8: Management | J8: Seal
A9: Safety | C9: Closed | J9: Filter
A10: Other | C10: Cancelled | J10: Other
